{
 "cells": [
  {
   "cell_type": "markdown",
   "metadata": {},
   "source": [
    "Testing "
   ]
  },
  {
   "cell_type": "code",
   "execution_count": 5,
   "metadata": {},
   "outputs": [
    {
     "ename": "AssertionError",
     "evalue": "Should be 6",
     "output_type": "error",
     "traceback": [
      "\u001b[1;31m---------------------------------------------------------------------------\u001b[0m",
      "\u001b[1;31mAssertionError\u001b[0m                            Traceback (most recent call last)",
      "Cell \u001b[1;32mIn[5], line 9\u001b[0m\n\u001b[0;32m      7\u001b[0m \u001b[39mif\u001b[39;00m \u001b[39m__name__\u001b[39m\u001b[39m==\u001b[39m\u001b[39m\"\u001b[39m\u001b[39m__main__\u001b[39m\u001b[39m\"\u001b[39m:\n\u001b[0;32m      8\u001b[0m     test_sum()\n\u001b[1;32m----> 9\u001b[0m     test_sum_tuple()\n\u001b[0;32m     10\u001b[0m     \u001b[39mprint\u001b[39m(\u001b[39m\"\u001b[39m\u001b[39mEverything Passed\u001b[39m\u001b[39m\"\u001b[39m)\n",
      "Cell \u001b[1;32mIn[5], line 5\u001b[0m, in \u001b[0;36mtest_sum_tuple\u001b[1;34m()\u001b[0m\n\u001b[0;32m      4\u001b[0m \u001b[39mdef\u001b[39;00m \u001b[39mtest_sum_tuple\u001b[39m():\n\u001b[1;32m----> 5\u001b[0m     \u001b[39massert\u001b[39;00m \u001b[39msum\u001b[39m((\u001b[39m1\u001b[39m, \u001b[39m2\u001b[39m, \u001b[39m2\u001b[39m))\u001b[39m==\u001b[39m\u001b[39m6\u001b[39m, \u001b[39m\"\u001b[39m\u001b[39mShould be 6\u001b[39m\u001b[39m\"\u001b[39m\n",
      "\u001b[1;31mAssertionError\u001b[0m: Should be 6"
     ]
    }
   ],
   "source": [
    "def test_sum():\n",
    "    assert sum([1, 2, 3])==6, \"Should be 6\"\n",
    "\n",
    "def test_sum_tuple():\n",
    "    assert sum((1, 2, 2))==6, \"Should be 6\"\n",
    "\n",
    "if __name__==\"__main__\":\n",
    "    test_sum()\n",
    "    test_sum_tuple()\n",
    "    print(\"Everything Passed\")"
   ]
  },
  {
   "cell_type": "markdown",
   "metadata": {},
   "source": [
    "Writing Tests and Executing Tests - The test for finding the sum of integers ran and worked. The test for finding the sum of fraction ran with a failure, AssertionError: Fraction(9, 10) !=1."
   ]
  }
 ],
 "metadata": {
  "kernelspec": {
   "display_name": "Python 3.10.8 64-bit (microsoft store)",
   "language": "python",
   "name": "python3"
  },
  "language_info": {
   "codemirror_mode": {
    "name": "ipython",
    "version": 3
   },
   "file_extension": ".py",
   "mimetype": "text/x-python",
   "name": "python",
   "nbconvert_exporter": "python",
   "pygments_lexer": "ipython3",
   "version": "3.10.8"
  },
  "orig_nbformat": 4,
  "vscode": {
   "interpreter": {
    "hash": "bb11ed172502466d714f440f01099a84240a38da1952ffd18dc1886544b573fb"
   }
  }
 },
 "nbformat": 4,
 "nbformat_minor": 2
}
